## Math Ops Testing Code (Production Standards)



`mathops/mathops.go`

```go
package mathops

import "errors"

func Add(a, b int) int {
	return a + b
}

func Multiply(a, b int) int {
	return a * b
}

func Divide(a, b int)(int, error){
	if b == 0{
		return 0, errors.New("cannot divide by zero")
	}
	return a / b, nil 
}
```

`mathops/mathops_test.go`

```go
package mathops

import (
	"errors"
	"testing"
)

func TestAdd(t *testing.T){
	tests := []struct{
		name string 
		a,b int 
		expected int 
	}{
		{"positive numbers", 2, 3, 5},
		{"negative numbers", -1, -2, -3},
		{"zero", 0, 5, 5}, 
	}

	for _, tt := range tests{
		t.Run(tt.name, func(t *testing.T){
			result := Add(tt.a, tt.b)
			if result != tt.expected{
				t.Errorf("Add(%d, %d) = %d; want %d", tt.a, tt.b, result, tt.expected)
			}
		})
	}
}

func TestMultiply(t *testing.T){
	tests := []struct{
		name string
		a,b int 
		expected int 
	}{
		{"positive numbers", 2, 3, 6},
		{"negative numbers", -2, 3, -6},
		{"zero", 0, 5, 0},
	}

	for _, tt := range tests{
		t.Run(tt.name, func(t *testing.T){
			result := Multiply(tt.a, tt.b)
			if result != tt.expected{
				t.Errorf("Multiply(%d, %d) = %d; want %d", tt.a, tt.b, result, tt.expected)
			}
		})
	}
}

func TestDivide(t *testing.T){
	tests := []struct{
		name string 
		a, b int
		expected int 
		expectedErr error 
	}{	
		{"valid division", 6, 3, 2, nil},
		{"division by zero", 6, 0, 0, errors.New("cannot divide by zero")},
		{"negative division", -6, 3, -2, nil},
	}

	for _, tt := range tests{
		t.Run(tt.name, func(t *testing.T){
			result, err := Divide(tt.a, tt.b)

			// If we got an error but did not expect one, fail.
			if err != nil && tt.expectedErr == nil{
				t.Errorf("Divide(%d, %d) returned unexpected error: %v", tt.a, tt.b, err)
			}

			// If we got an error and expected one, check the error message matches.
			if err != nil && tt.expectedErr != nil && err.Error() != tt.expectedErr.Error(){
				t.Errorf("Divide(%d, %d) error = %v; want %v", tt.a, tt.b, err, tt.expectedErr)
			}

			// If no error occurred, verify the result is as expected.
			if err == nil && result != tt.expected{
				t.Errorf("Divide(%d, %d) = %d; want %d", tt.a, tt.b, result, tt.expected)
			}
		})
	}
}
```



```sh
mathops ➤ go test
PASS
ok      practice/mathops        0.001s
```



But if we try altering one of our functions

```go
func Divide(a, b int)(int, error){
	if b == 0{
		return 0, errors.New("cannot divide by zero")
	}
	return a / b * 0, nil 
}
```

```sh
mathops ➤ go test
--- FAIL: TestDivide (0.00s)
    --- FAIL: TestDivide/valid_division (0.00s)
        mathops_test.go:74: Divide(6, 3) = 0; want 2
    --- FAIL: TestDivide/negative_division (0.00s)
        mathops_test.go:74: Divide(-6, 3) = 0; want -2
FAIL
exit status 1
FAIL    practice/mathops        0.002s
```

